Workbook

Sheet 0. Tổng quan
A1: BShoes: Hệ thống quản lý & bán hàng cửa hàng giày
A2: WORKSHOP 2: Product Backlog, Release Backlog, Sprint Backlog & Ước lượng Story
A3: Phiên bản: v1.2 (chuẩn hóa Scrum: RQ -> PB -> Task, đánh số theo Sprint)
A4: Hạn hoàn thành: 30/09/2026
A6: Cấu trúc tài liệu (3 cấp, đánh số theo Sprint)
A7: Cấp 1, RQ (Request): yêu cầu từ actor, dạng As a / I want / So that -> Product Backlog
A8: Cấp 2, PB (Product Backlog Item): user story bóc từ RQ, có Priority/Sprint/Story Point -> Release Backlog
A9: Cấp 3, Task: mỗi PB chia thành nhiều Task -> Sprint Backlog (tách từng Sprint)
A11: Công thức ước lượng (theo tài liệu 'Ước lượng số lượng Story')
A12: UP (Điểm chưa hiệu chỉnh) = Loại tương tác + Quy tắc nghiệp vụ + Số thực thể + Thao tác dữ liệu (mỗi mục 1..3)
A13: AP (Điểm đã hiệu chỉnh) = UP × C (C = hệ số nhân)
A14: PPS (Điểm cho mỗi Story) = (AP × ED) / 36
... A17: Kết quả tính cho nhóm
A18: ED của nhóm | B18: ='5. ED (Môi trường)'!D23
A19: Hệ số môi trường ED/36 | B19: ='5. ED (Môi trường)'!D24
A20: C (hệ số nhân) | B20: ='6. Ước lượng Story'!C2
A22: Nhóm thực hiện
A23: Vai trò | B23: Thành viên | C23: Trách nhiệm
A24: PO | B24: [Thành viên 1] | C24: Product Owner: thu thập yêu cầu, viết Product Backlog, sắp ưu tiên, nghiệm thu
A25: SM | B25: [Thành viên 2] | C25: Scrum Master: điều phối sprint, gỡ vướng, theo dõi tiến độ
A26: DEV1 | B26: [Thành viên 3] | C26: Dev Backend: Spring Boot / JPA / SQL Server
A27: DEV2 | B27: [Thành viên 4] | C27: Dev Frontend: Vue 3 SPA
A28: DEV3 | B28: [Thành viên 5] | C28: Dev Fullstack: tích hợp API, hỗ trợ 2 phía
A29: QC | B29: [Thành viên 6] | C29: Kiểm thử: test chức năng, báo lỗi, xác nhận Done

Sheet 1. Product Backlog
A1: Product Backlog cấp Request (RQ): As a / I want / So that
A3: ID | B3: As a/an [role] | C3: I want to [goal] | D3: So that [reason] | E3: Priority | F3: Business Value | G3: Acceptance Criteria | H3: State
A4: RQ-01 | B4: Là nhân viên | C4: đăng nhập và được cấp đúng quyền theo vai trò | D4: dùng hệ thống an toàn, đúng phạm vi | E4: 1 | F4: High | G4: Chức năng hoạt động đúng và được PO nghiệm thu | H4: New
A5: RQ-02 | B5: Là quản trị viên | C5: quản lý nhân viên và phân quyền truy cập theo vai trò và theo từng người | D5: kiểm soát ai được dùng chức năng nào | E5: 1 | F5: High | G5: Chức năng hoạt động đúng và được PO nghiệm thu | H5: New
A6: RQ-03 | B6: Là quản lý | C6: quản lý sản phẩm, biến thể màu/size, tồn kho, danh mục và thuộc tính | D6: quản trị được toàn bộ hàng hóa | E6: 2 | F6: High | G6: Chức năng hoạt động đúng và được PO nghiệm thu | H6: New
A7: RQ-04 | B7: Là nhân viên bán hàng | C7: bán tại quầy, tự trừ kho, thanh toán và in hóa đơn | D7: phục vụ khách nhanh và chính xác | E7: 1 | F7: High | G7: Chức năng hoạt động đúng và được PO nghiệm thu | H7: New
A8: RQ-05 | B8: Là nhân viên giao hàng | C8: tạo và theo dõi đơn giao, xử lý trả hàng và hoàn kho | D8: giao hàng tận nơi có kiểm soát | E8: 2 | F8: Medium | G8: Chức năng hoạt động đúng và được PO nghiệm thu | H8: New
A9: RQ-06 | B9: Là quản lý | C9: quản lý khách hàng và địa chỉ giao hàng | D9: chăm sóc khách và giao đúng địa chỉ | E9: 2 | F9: Medium | G9: Chức năng hoạt động đúng và được PO nghiệm thu | H9: New
A10: RQ-07 | B10: Là khách hàng | C10: xem cửa hàng online, mua giao tận nhà và đặt trước mẫu hết hàng | D10: mua sắm online thuận tiện | E10: 3 | F10: Medium | G10: Chức năng hoạt động đúng và được PO nghiệm thu | H10: New
A11: RQ-08 | B11: Là kế toán và chủ shop | C11: xem KPI, doanh thu, lợi nhuận, ROI và xuất báo cáo | D11: ra quyết định kinh doanh dựa trên dữ liệu | E11: 3 | F11: High | G11: Chức năng hoạt động đúng và được PO nghiệm thu | H11: New
A12: RQ-09 | B12: Là nhân viên bảo hành và quản lý | C12: tiếp nhận và xử lý bảo hành, quản lý phiếu giảm giá và khuyến mãi | D12: chăm sóc khách sau bán và thúc đẩy doanh số | E12: 3 | F12: Medium | G12: Chức năng hoạt động đúng và được PO nghiệm thu | H12: New

Sheet 2. Release Backlog
A1: Release Backlog: user story theo Backlog (RQ) và Sprint
A3: Backlog ID | B3: Backlog | C3: As a/an [role] | D3: I want to [goal] | E3: So that [reason] | F3: Story ID | G3: Priority | H3: Business Value | I3: Sprint# | J3: State | K3: Story Points
A4: RQ-01 | B4: Đăng nhập | C4: Là Nhân viên | D4: đăng nhập để dùng hệ thống theo đúng quyền | E4: Xác thực tài khoản, lấy vai trò & quyền truy cập màn hình | F4: PB-01 | G4: 1 | H4: High | I4: 1 | J4: New | K4: =VLOOKUP(F4,'6. Ước lượng Story'!$A$5:$L$44,12,FALSE)
A5: RQ-02 | B5: Nhân viên & Phân quyền | C5: Là Quản trị | D5: CRUD nhân viên | E5: Thêm/sửa/xóa/tìm nhân viên, gán vai trò | F5: PB-02 | G5: 1 | H5: High | I5: 1 | J5: New | K5: =VLOOKUP(F5,'6. Ước lượng Story'!$A$5:$L$44,12,FALSE)
A6: RQ-02 | B6: Nhân viên & Phân quyền | C6: Là Quản trị | D6: đặt bộ quyền mặc định cho từng vai trò | E6: Vai trò là template: bộ quyền mặc định chép cho nhân viên khi tạo mới hoặc đổi vai trò | F6: PB-03 | G6: 1 | H6: High | I6: 1 | J6: New | K6: =VLOOKUP(F6,'6. Ước lượng Story'!$A$5:$L$44,12,FALSE)
A7: RQ-02 | B7: Nhân viên & Phân quyền | C7: Là Quản trị | D7: phân quyền truy cập cho từng nhân viên | E7: Lưới nhân viên x màn hình; vai trò chỉ là template, mỗi người mở rộng thêm được | F7: PB-04 | G7: 1 | H7: High | I7: 1 | J7: New | K7: =VLOOKUP(F7,'6. Ước lượng Story'!$A$5:$L$44,12,FALSE)
A8: RQ-03 | B8: Quản lý sản phẩm & danh mục | C8: Là Quản lý | D8: CRUD sản phẩm để quản trị danh mục hàng | E8: Thêm/sửa/xóa mềm/khôi phục/thùng rác sản phẩm | F8: PB-05 | G8: 2 | H8: High | I8: 2 | J8: New | K8: =VLOOKUP(F8,'6. Ước lượng Story'!$A$5:$L$44,12,FALSE)
A9: RQ-03 | B9: Quản lý sản phẩm & danh mục | C9: Là Quản lý | D9: quản lý biến thể (màu/size/giá/giá nhập) | E9: CRUD biến thể, sửa giá bán & giá vốn, trạng thái bán | F9: PB-06 | G9: 2 | H9: High | I9: 2 | J9: New | K9: =VLOOKUP(F9,'6. Ước lượng Story'!$A$5:$L$44,12,FALSE)
A10: RQ-03 | B10: Quản lý sản phẩm & danh mục | C10: Là Nhân viên kho | D10: nhập kho để tăng tồn | E10: Cộng số lượng tồn cho biến thể | F10: PB-07 | G10: 2 | H10: Medium | I10: 2 | J10: New | K10: =VLOOKUP(F10,'6. Ước lượng Story'!$A$5:$L$44,12,FALSE)
A11: RQ-03 | B11: Quản lý sản phẩm & danh mục | C11: Là Quản lý | D11: quản lý danh mục và xếp sản phẩm vào danh mục | E11: CRUD danh mục, gán/bỏ sản phẩm khỏi danh mục | F11: PB-08 | G11: 2 | H11: Medium | I11: 2 | J11: New | K11: =VLOOKUP(F11,'6. Ước lượng Story'!$A$5:$L$44,12,FALSE)
A12: RQ-03 | B12: Quản lý sản phẩm & danh mục | C12: Là Quản lý | D12: quản lý thuộc tính sản phẩm | E12: CRUD 8 nhóm thuộc tính, lọc theo đúng loại | F12: PB-09 | G12: 2 | H12: Medium | I12: 2 | J12: New | K12: =VLOOKUP(F12,'6. Ước lượng Story'!$A$5:$L$44,12,FALSE)
A13: RQ-03 | B13: Quản lý sản phẩm & danh mục | C13: Là Quản lý | D13: thao tác sản phẩm, danh mục, thuộc tính trong cùng một màn | E13: Gộp danh mục và thuộc tính thành tab của Quản lý sản phẩm, bớt nhảy màn | F13: PB-10 | G13: 3 | H13: Low | I13: 2 | J13: New | K13: =VLOOKUP(F13,'6. Ước lượng Story'!$A$5:$L$44,12,FALSE)
A14: RQ-04 | B14: Bán hàng tại quầy (POS) | C14: Là Nhân viên | D14: tạo hóa đơn chờ để bắt đầu một lượt bán | E14: Sinh mã HĐ, trạng thái Chờ, tối đa 3 hóa đơn chờ | F14: PB-11 | G14: 1 | H14: High | I14: 3 | J14: New | K14: =VLOOKUP(F14,'6. Ước lượng Story'!$A$5:$L$44,12,FALSE)
A15: RQ-04 | B15: Bán hàng tại quầy (POS) | C15: Là Nhân viên | D15: thêm hàng vào giỏ và hệ thống tự trừ kho | E15: Thêm dòng hóa đơn, trừ tồn nguyên tử, tính lại tổng tiền | F15: PB-12 | G15: 1 | H15: High | I15: 3 | J15: New | K15: =VLOOKUP(F15,'6. Ước lượng Story'!$A$5:$L$44,12,FALSE)
... A43: RQ-09 | B43: Sau bán hàng: Bảo hành & Khuyến mãi | C43: Là Quản lý | D43: quản lý phiếu giảm giá | E43: CRUD phiếu, thời hạn, điều kiện, trạng thái | F43: PB-40 | G43: 2 | H43: Medium | I43: 6 | J43: New | K43: =VLOOKUP(F43,'6. Ước lượng Story'!$A$5:$L$44,12,FALSE)
F44: TỔNG | K44: =SUM(K4:K43)

Sheet 3. Sprint Planning
A1: Sprint Duration: 2 tuần
A3: Sprint | B3: Mục tiêu Sprint (Sprint Goal) | C3: Số User Story | D3: Tổng Story Points | E3: Tổng giờ task
A4: Sprint 1 | B4: Nền tảng: đăng nhập, nhân viên và phân quyền | C4: =COUNTIF('2. Release Backlog'!$I$4:$I$43,1) | D4: =SUMIF('2. Release Backlog'!$I$4:$I$43,1,'2. Release Backlog'!$K$4:$K$43) | E4: =SUMIF('4. Sprint Backlog'!$F$2:$F$600,1,'4. Sprint Backlog'!$G$2:$G$600)
A5: Sprint 2 | B5: Quản lý sản phẩm: sản phẩm, biến thể, nhập kho, danh mục, thuộc tính | C5: =COUNTIF('2. Release Backlog'!$I$4:$I$43,2) | D5: =SUMIF('2. Release Backlog'!$I$4:$I$43,2,'2. Release Backlog'!$K$4:$K$43) | E5: =SUMIF('4. Sprint Backlog'!$F$2:$F$600,2,'4. Sprint Backlog'!$G$2:$G$600)
A6: Sprint 3 | B6: Bán hàng tại quầy: giỏ hàng trừ kho, thanh toán, in hóa đơn, quét QR | C6: =COUNTIF('2. Release Backlog'!$I$4:$I$43,3) | D6: =SUMIF('2. Release Backlog'!$I$4:$I$43,3,'2. Release Backlog'!$K$4:$K$43) | E6: =SUMIF('4. Sprint Backlog'!$F$2:$F$600,3,'4. Sprint Backlog'!$G$2:$G$600)
A7: Sprint 4 | B7: Đơn đặt hàng, giao hàng, trả hàng và quản lý khách hàng | C7: =COUNTIF('2. Release Backlog'!$I$4:$I$43,4) | D7: =SUMIF('2. Release Backlog'!$I$4:$I$43,4,'2. Release Backlog'!$K$4:$K$43) | E7: =SUMIF('4. Sprint Backlog'!$F$2:$F$600,4,'4. Sprint Backlog'!$G$2:$G$600)
A8: Sprint 5 | B8: Cửa hàng online: trang chủ, chi tiết, giỏ hàng, đặt hàng COD, đặt trước | C8: =COUNTIF('2. Release Backlog'!$I$4:$I$43,5) | D8: =SUMIF('2. Release Backlog'!$I$4:$I$43,5,'2. Release Backlog'!$K$4:$K$43) | E8: =SUMIF('4. Sprint Backlog'!$F$2:$F$600,5,'4. Sprint Backlog'!$G$2:$G$600)
A9: Sprint 6 | B9: Dashboard doanh thu, bảo hành và khuyến mãi | C9: =COUNTIF('2. Release Backlog'!$I$4:$I$43,6) | D9: =SUMIF('2. Release Backlog'!$I$4:$I$43,6,'2. Release Backlog'!$K$4:$K$43) | E9: =SUMIF('4. Sprint Backlog'!$F$2:$F$600,6,'4. Sprint Backlog'!$G$2:$G$600)
B10: TỔNG | C10: =SUM(C4:C9) | D10: =SUM(D4:D9) | E10: =SUM(E4:E9)

Sheet 4. Sprint Backlog
A1: Task ID | B1: Task | C1: Mô tả công việc | D1: Story ID | E1: Backlog ID | F1: Sprint# | G1: Estimate (giờ) | H1: Phụ trách | I1: Trạng thái
A2: Sprint 1: Nền tảng: đăng nhập, nhân viên và phân quyền
A3: T-01 | B3: Thiết kế bảng nhan_vien / vai_tro | C3: Chuẩn hóa CSDL, thêm cột quyen | D3: PB-01 | E3: RQ-01 | F3: 1 | G3: 4 | H3: DEV1 | I3: To Do
A4: T-02 | B4: API POST /api/auth/login | C4: Xác thực tài khoản, trả vai trò + quyền | D4: PB-01 | E4: RQ-01 | F4: 1 | G4: 4 | H4: DEV1 | I4: To Do
A5: T-03 | B5: Màn hình đăng nhập | C5: Form + báo lỗi sai tài khoản | D5: PB-01 | E5: RQ-01 | F5: 1 | G5: 3 | H5: DEV2 | I5: To Do
A6: T-04 | B6: Lưu phiên đăng nhập | C6: Store useAuth + localStorage, chặn route | D6: PB-01 | E6: RQ-01 | F6: 1 | G6: 4 | H6: DEV2 | I6: To Do
A7: T-05 | B7: Test đăng nhập | C7: Sai/đúng mật khẩu, hết phiên | D7: PB-01 | E7: RQ-01 | F7: 1 | G7: 2 | H7: QC | I7: To Do
A8: T-06 | B8: API nhân viên CRUD | C8: Thêm/sửa/xóa/tìm nhân viên | D8: PB-02 | E8: RQ-02 | F8: 1 | G8: 4 | H8: DEV1 | I8: To Do
A9: T-07 | B9: Màn nhân viên | C9: Bảng + modal | D9: PB-02 | E9: RQ-02 | F9: 1 | G9: 4 | H9: DEV2 | I9: To Do
A10: T-08 | B10: Cột vai_tro.quyen + API phân quyền | C10: GET/PUT quyền theo vai trò | D10: PB-03 | E10: RQ-02 | F10: 1 | G10: 4 | H10: DEV1 | I10: To Do
A11: T-09 | B11: Màn phân quyền | C11: Vai trò x màn hình, tick chọn, lưu | D11: PB-03 | E11: RQ-02 | F11: 1 | G11: 5 | H11: DEV2 | I11: To Do
A12: T-10 | B12: Ẩn menu & chặn route theo quyền | C12: Sidebar + router guard | D12: PB-03 | E12: RQ-02 | F12: 1 | G12: 4 | H12: DEV3 | I12: To Do
A13: T-11 | B13: Test phân quyền | C13: Đăng nhập từng vai trò, kiểm menu | D13: PB-03 | E13: RQ-02 | F13: 1 | G13: 3 | H13: QC | I13: To Do
A14: T-12 | B14: Đổi vai trò thành template | C14: vai_tro.quyen hạ xuống thành bộ quyền mặc định, không còn là quyền hiệu lực | D14: PB-03 | E14: RQ-02 | F14: 1 | G14: 2 | H14: DEV1 | I14: To Do
... A21: T-19 | B21: Unit test logic phân quyền | C21: 11 test: ngoại lệ ADMIN, parse template, khử trùng, chống N+1 | D21: PB-04 | E21: RQ-02 | F21: 1 | G21: 4 | H21: QC | I21: To Do
A22: Sprint 2: Quản lý sản phẩm: sản phẩm, biến thể, nhập kho, danh mục, thuộc tính
A23: T-20 | B23: API /san-pham-ql CRUD | C23: Thêm/sửa/tìm/xóa mềm/khôi phục/thùng rác | D23: PB-05 | E23: RQ-03 | F23: 2 | G23: 6 | H23: DEV1 | I23: To Do
A24: T-21 | B24: Màn quản lý sản phẩm | C24: Bảng + form chi tiết + chọn ảnh | D24: PB-05 | E24: RQ-03 | F24: 2 | G24: 6 | H24: DEV2 | I24: To Do
A25: T-22 | B25: Test CRUD sản phẩm | C25: Thêm/sửa/ẩn/khôi phục | D25: PB-05 | E25: RQ-03 | F25: 2 | G25: 3 | H25: QC | I25: To Do
A26: T-23 | B26: API biến thể CRUD | C26: Tạo/sửa/xóa mềm biến thể, gộp về 1 controller | D26: PB-06 | E26: RQ-03 | F26: 2 | G26: 5 | H26: DEV1 | I26: To Do
A27: T-24 | B27: Thêm cột gia_nhap | C27: CSDL + entity + DTO | D27: PB-06 | E27: RQ-03 | F27: 2 | G27: 3 | H27: DEV1 | I27: To Do
A28: T-25 | B28: Tab Sản phẩm chi tiết | C28: Sửa giá bán/giá vốn/tồn/màu/size | D28: PB-06 | E28: RQ-03 | F28: 2 | G28: 5 | H28: DEV2 | I28: To Do
A29: T-26 | B29: API POST /{id}/nhap-kho | C29: Cộng tồn, bật lại trạng thái bán | D29: PB-07 | E29: RQ-03 | F29: 2 | G29: 2 | H29: DEV1 | I29: To Do
A30: T-27 | B30: Ô nhập kho trên form biến thể | C30: Nhập số lượng + nút Nhập | D30: PB-07 | E30: RQ-03 | F30: 2 | G30: 2 | H30: DEV2 | I30: To Do
A31: T-28 | B31: API gán danh mục | C31: PUT /san-pham-ql/{id}/danh-muc | D31: PB-08 | E31: RQ-03 | F31: 2 | G31: 3 | H31: DEV1 | I31: To Do
A32: T-29 | B32: Màn danh mục + gán sản phẩm | C32: Danh sách + thêm/bỏ sản phẩm | D32: PB-08 | E32: RQ-03 | F32: 2 | G32: 5 | H32: DEV2 | I32: To Do
A33: T-30 | B33: API CRUD 8 nhóm thuộc tính | C33: Chất liệu, màu, size, kiểu... | D33: PB-09 | E33: RQ-03 | F33: 2 | G33: 4 | H33: DEV1 | I33: To Do
A34: T-31 | B34: Màn thuộc tính + lọc theo loại | C34: Chọn loại -> chỉ hiện đúng loại đó | D34: PB-09 | E34: RQ-03 | F34: 2 | G34: 5 | H34: DEV2 | I34: To Do
... A36: T-33 | B36: Gộp tab vào màn sản phẩm | C36: 4 tab, panel lazy chỉ gọi API khi mở | D36: PB-10 | E36: RQ-03 | F36: 2 | G36: 2 | H36: DEV2 | I36: To Do
A37: Sprint 3: Bán hàng tại quầy: giỏ hàng trừ kho, thanh toán, in hóa đơn, quét QR
A38: T-34 | B38: API POST /hoa-don/create-empty | C38: Sinh mã HĐ, trạng thái 0, giới hạn 3 đơn chờ | D38: PB-11 | E38: RQ-04 | F38: 3 | G38: 4 | H38: DEV1 | I38: To Do
A39: T-35 | B39: Giao diện danh sách hóa đơn chờ | C39: Bảng hóa đơn + nút Tạo hóa đơn | D39: PB-11 | E39: RQ-04 | F39: 3 | G39: 3 | H39: DEV2 | I39: To Do
A40: T-36 | B40: Test tạo hóa đơn | C40: Tạo/chuyển/giới hạn 3 đơn | D40: PB-11 | E40: RQ-04 | F40: 3 | G40: 2 | H40: QC | I40: To Do
A41: T-37 | B41: Query trừ kho nguyên tử | C41: UPDATE ... WHERE so_luong_ton >= n | D41: PB-12 | E41: RQ-04 | F41: 3 | G41: 4 | H41: DEV1 | I41: To Do
A42: T-38 | B42: API POST /hoa-don/{id}/items | C42: Thêm dòng + trừ kho + tính tổng | D42: PB-12 | E42: RQ-04 | F42: 3 | G42: 5 | H42: DEV1 | I42: To Do
A43: T-39 | B43: API sửa/xóa dòng giỏ | C43: PUT/DELETE + hoàn kho theo delta | D43: PB-12 | E43: RQ-04 | F43: 3 | G43: 4 | H43: DEV1 | I43: To Do
A44: T-40 | B44: Giỏ hàng nối server | C44: Thêm/tăng/giảm/xóa gọi API, đồng bộ tồn | D44: PB-12 | E44: RQ-04 | F44: 3 | G44: 6 | H44: DEV3 | I44: To Do
A45: T-41 | B45: Test trừ kho | C45: Thêm/bớt/xóa, kiểm tồn khớp, chặn quá tồn | D45: PB-12 | E45: RQ-04 | F45: 3 | G45: 4 | H45: QC | I45: To Do
A46: T-42 | B46: API tính giảm giá | C46: Gọi hàm tinh_tien_giam_gia | D46: PB-13 | E46: RQ-04 | F46: 3 | G46: 3 | H46: DEV1 | I46: To Do
A47: T-43 | B47: Chọn phiếu giảm giá ở POS | C47: Dropdown + tính lại thành tiền | D47: PB-13 | E47: RQ-04 | F47: 3 | G47: 3 | H47: DEV2 | I47: To Do
...

Sheet 5. ED (Môi trường)
A1: ED: Đánh giá môi trường (Environment Degree)
A2: Mỗi yếu tố chấm 0 hoặc 2 (2 = thuận lợi cho nhóm). Tổng tối đa = 18 yếu tố × 2 = 36.
A4: Khía cạnh | B4: Yếu tố | C4: Khoảng giá trị | D4: Giá trị (0/2) | E4: Lý do chấm điểm của nhóm
A5: Khía cạnh tổ chức | B5: Đã có những phòng ban khác nhau cùng làm việc thành công trong một dự án Scrum? | C5: 0 / 2 | D5: 0 | E5: Nhóm môn học, chưa có nhiều phòng ban cùng làm Scrum
A6: Khía cạnh tổ chức | B6: Có sự chống đối mạnh mẽ với Scrum trong tổ chức? | C6: 0 / 2 | D6: 2 | E6: Không có chống đối, cả nhóm hợp tác tích cực
A7: Khía cạnh tổ chức | B7: Có tồn tại sự hỗ trợ lớn về Scrum giữa những phòng ban khác nhau trong công ty? | C7: 0 / 2 | D7: 0 | E7: Chưa có cơ chế hỗ trợ liên phòng ban
A8: Khía cạnh hạ tầng phát triển | B8: Kiểm thử tự động đã được áp dụng và trở thành kỹ thuật phổ biến? | C8: 0 / 2 | D8: 0 | E8: Dự án chưa có bộ test tự động
A9: Khía cạnh hạ tầng phát triển | B9: Kiểm thử tích hợp liên tục (CI) đã phổ biến? | C9: 0 / 2 | D9: 0 | E9: Chưa dựng pipeline CI
A10: Khía cạnh hạ tầng phát triển | B10: Môi trường build hàng ngày đã phổ biến? | C10: 0 / 2 | D10: 2 | E10: Build mvn/npm chạy được hằng ngày, đã kiểm chứng
A11: Khía cạnh nhóm | B11: Scrum là hoàn toàn mới đối với nhóm? | C11: 0 / 2 | D11: 0 | E11: Scrum còn khá mới với nhóm
A12: Khía cạnh nhóm | B12: Các thành viên trong nhóm đã từng làm việc thành công với nhau? | C12: 0 / 2 | D12: 2 | E12: Nhóm đã từng hợp tác ở dự án trước
A13: Khía cạnh nhóm | B13: Các thành viên trong nhóm hiểu và tôn trọng lẫn nhau? | C13: 0 / 2 | D13: 2 | E13: Tinh thần hợp tác tích cực
A14: Khía cạnh công nghệ | B14: Nhóm phát triển có nhiều kinh nghiệm với ngôn ngữ lập trình? | C14: 0 / 2 | D14: 0 | E14: Trình độ IT của nhóm còn hạn chế
A15: Khía cạnh công nghệ | B15: Thành viên có nhiều kinh nghiệm với công nghệ được dùng (Spring Boot/Vue/SQL Server)? | C15: 0 / 2 | D15: 0 | E15: Công nghệ mới với phần lớn thành viên
A16: Khía cạnh công nghệ | B16: Môi trường sản xuất với Scrum đã sẵn sàng chưa? | C16: 0 / 2 | D16: 0 | E16: Chưa có môi trường production/CSDL ổn định
... A22: Khía cạnh nghiệp vụ | B22: Product Owner đã từng thành công với Scrum trước đây chưa? | C22: 0 / 2 | D22: 0 | E22: Chưa từng dẫn dắt dự án Scrum thành công
B23: ED: TỔNG ĐIỂM MÔI TRƯỜNG | D23: =SUM(D5:D22) | E23: Tối đa 36
B24: Hệ số môi trường = ED / 36 | D24: =D23/36
B26: Tổng theo từng khía cạnh (tham khảo)
B27: Khía cạnh tổ chức | D27: =SUM(D5,D6,D7) | E27: Tối đa 6
B28: Khía cạnh hạ tầng phát triển | D28: =SUM(D8,D9,D10) | E28: Tối đa 6
B29: Khía cạnh nhóm | D29: =SUM(D11,D12,D13) | E29: Tối đa 6
B30: Khía cạnh công nghệ | D30: =SUM(D14,D15,D16) | E30: Tối đa 6
B31: Khía cạnh qui trình | D31: =SUM(D17,D18,D19) | E31: Tối đa 6
B32: Khía cạnh nghiệp vụ | D32: =SUM(D20,D21,D22) | E32: Tối đa 6

Sheet 6. Ước lượng Story
A1: Ước lượng số lượng Story: UP / AP / PPS
A2: C (hệ số nhân) = | C2: 1 | D2: ED = | E2: ='5. ED (Môi trường)'!D23 | F2: PPS = (AP × ED)/36 ; AP = UP × C ; UP = tổng 4 tiêu chí (mỗi tiêu chí 1..3)
A4: ID | B4: User Story | C4: Loại tương tác (1-3) | D4: Quy tắc nghiệp vụ (1-3) | E4: Số thực thể (1-3) | F4: Thao tác dữ liệu (1-3) | G4: UP | H4: C | I4: AP | J4: ED | K4: PPS | L4: Story Point (Fibonacci)
A5: PB-01 | B5: Là nhân viên, tôi muốn đăng nhập để dùng hệ thống theo đúng quyền | C5: 2 | D5: 2 | E5: 2 | F5: 1 | G5: =SUM(C5:F5) | H5: =$C$2 | I5: =G5*H5 | J5: =$E$2 | K5: =I5*J5/36 | L5: =IF(K5<=1,1,IF(K5<=2,2,IF(K5<=3,3,IF(K5<=5,5,IF(K5<=8,8,IF(K5<=13,13,21))))))
A6: PB-02 | B6: Là quản trị, tôi muốn CRUD nhân viên | C6: 2 | D6: 2 | E6: 2 | F6: 3 | G6: =SUM(C6:F6) | H6: =$C$2 | I6: =G6*H6 | J6: =$E$2 | K6: =I6*J6/36 | L6: =IF(K6<=1,1,IF(K6<=2,2,IF(K6<=3,3,IF(K6<=5,5,IF(K6<=8,8,IF(K6<=13,13,21))))))
A7: PB-03 | B7: Là quản trị, tôi muốn đặt bộ quyền mặc định cho từng vai trò | C7: 2 | D7: 3 | E7: 2 | F7: 2 | G7: =SUM(C7:F7) | H7: =$C$2 | I7: =G7*H7 | J7: =$E$2 | K7: =I7*J7/36 | L7: =IF(K7<=1,1,IF(K7<=2,2,IF(K7<=3,3,IF(K7<=5,5,IF(K7<=8,8,IF(K7<=13,13,21))))))
A8: PB-04 | B8: Là quản trị, tôi muốn phân quyền truy cập cho từng nhân viên | C8: 3 | D8: 3 | E8: 3 | F8: 3 | G8: =SUM(C8:F8) | H8: =$C$2 | I8: =G8*H8 | J8: =$E$2 | K8: =I8*J8/36 | L8: =IF(K8<=1,1,IF(K8<=2,2,IF(K8<=3,3,IF(K8<=5,5,IF(K8<=8,8,IF(K8<=13,13,21))))))
A9: PB-05 | B9: Là quản lý, tôi muốn CRUD sản phẩm để quản trị danh mục hàng | C9: 2 | D9: 3 | E9: 3 | F9: 3 | G9: =SUM(C9:F9) | H9: =$C$2 | I9: =G9*H9 | J9: =$E$2 | K9: =I9*J9/36 | L9: =IF(K9<=1,1,IF(K9<=2,2,IF(K9<=3,3,IF(K9<=5,5,IF(K9<=8,8,IF(K9<=13,13,21))))))
A10: PB-06 | B10: Là quản lý, tôi muốn quản lý biến thể (màu/size/giá/giá nhập) | C10: 2 | D10: 3 | E10: 3 | F10: 3 | G10: =SUM(C10:F10) | H10: =$C$2 | I10: =G10*H10 | J10: =$E$2 | K10: =I10*J10/36 | L10: =IF(K10<=1,1,IF(K10<=2,2,IF(K10<=3,3,IF(K10<=5,5,IF(K10<=8,8,IF(K10<=13,13,21))))))
A11: PB-07 | B11: Là nhân viên kho, tôi muốn nhập kho để tăng tồn | C11: 1 | D11: 1 | E11: 1 | F11: 1 | G11: =SUM(C11:F11) | H11: =$C$2 | I11: =G11*H11 | J11: =$E$2 | K11: =I11*J11/36 | L11: =IF(K11<=1,1,IF(K11<=2,2,IF(K11<=3,3,IF(K11<=5,5,IF(K11<=8,8,IF(K11<=13,13,21))))))
A12: PB-08 | B12: Là quản lý, tôi muốn quản lý danh mục và xếp sản phẩm vào danh mục | C12: 2 | D12: 2 | E12: 2 | F12: 2 | G12: =SUM(C12:F12) | H12: =$C$2 | I12: =G12*H12 | J12: =$E$2 | K12: =I12*J12/36 | L12: =IF(K12<=1,1,IF(K12<=2,2,IF(K12<=3,3,IF(K12<=5,5,IF(K12<=8,8,IF(K12<=13,13,21))))))
A13: PB-09 | B13: Là quản lý, tôi muốn quản lý thuộc tính sản phẩm | C13: 2 | D13: 2 | E13: 3 | F13: 3 | G13: =SUM(C13:F13) | H13: =$C$2 | I13: =G13*H13 | J13: =$E$2 | K13: =I13*J13/36 | L13: =IF(K13<=1,1,IF(K13<=2,2,IF(K13<=3,3,IF(K13<=5,5,IF(K13<=8,8,IF(K13<=13,13,21))))))
A14: PB-10 | B14: Là quản lý, tôi muốn thao tác sản phẩm, danh mục, thuộc tính trong cùng một màn | C14: 2 | D14: 1 | E14: 1 | F14: 1 | G14: =SUM(C14:F14) | H14: =$C$2 | I14: =G14*H14 | J14: =$E$2 | K14: =I14*J14/36 | L14: =IF(K14<=1,1,IF(K14<=2,2,IF(K14<=3,3,IF(K14<=5,5,IF(K14<=8,8,IF(K14<=13,13,21))))))
A15: PB-11 | B15: Là nhân viên, tôi muốn tạo hóa đơn chờ để bắt đầu một lượt bán | C15: 2 | D15: 2 | E15: 2 | F15: 2 | G15: =SUM(C15:F15) | H15: =$C$2 | I15: =G15*H15 | J15: =$E$2 | K15: =I15*J15/36 | L15: =IF(K15<=1,1,IF(K15<=2,2,IF(K15<=3,3,IF(K15<=5,5,IF(K15<=8,8,IF(K15<=13,13,21))))))
A16: PB-12 | B16: Là nhân viên, tôi muốn thêm hàng vào giỏ và hệ thống tự trừ kho | C16: 3 | D16: 3 | E16: 3 | F16: 3 | G16: =SUM(C16:F16) | H16: =$C$2 | I16: =G16*H16 | J16: =$E$2 | K16: =I16*J16/36 | L16: =IF(K16<=1,1,IF(K16<=2,2,IF(K16<=3,3,IF(K16<=5,5,IF(K16<=8,8,IF(K16<=13,13,21))))))
... A44: PB-40 | B44: Là quản lý, tôi muốn quản lý phiếu giảm giá | C44: 2 | D44: 3 | E44: 1 | F44: 3 | G44: =SUM(C44:F44) | H44: =$C$2 | I44: =G44*H44 | J44: =$E$2 | K44: =I44*J44/36 | L44: =IF(K44<=1,1,IF(K44<=2,2,IF(K44<=3,3,IF(K44<=5,5,IF(K44<=8,8,IF(K44<=13,13,21))))))
B45: TỔNG | G45: =SUM(G5:G44) | K45: =SUM(K5:K44) | L45: =SUM(L5:L44)
